Exception on /api/submitOrder [POST]
Traceback (most recent call last):
  File "C:\Users\buset\anaconda3\envs\atc_pycharm\lib\site-packages\pandas\core\indexes\base.py", line 3621, in get_loc
    return self._engine.get_loc(casted_key)
  File "pandas\_libs\index.pyx", line 136, in pandas._libs.index.IndexEngine.get_loc
  File "pandas\_libs\index.pyx", line 163, in pandas._libs.index.IndexEngine.get_loc
  File "pandas\_libs\hashtable_class_helper.pxi", line 5198, in pandas._libs.hashtable.PyObjectHashTable.get_item
  File "pandas\_libs\hashtable_class_helper.pxi", line 5206, in pandas._libs.hashtable.PyObjectHashTable.get_item
KeyError: 'weight'

The above exception was the direct cause of the following exception:

Traceback (most recent call last):
  File "C:\Users\buset\anaconda3\envs\atc_pycharm\lib\site-packages\flask\app.py", line 2077, in wsgi_app
    response = self.full_dispatch_request()
  File "C:\Users\buset\anaconda3\envs\atc_pycharm\lib\site-packages\flask\app.py", line 1525, in full_dispatch_request
    rv = self.handle_user_exception(e)
  File "C:\Users\buset\anaconda3\envs\atc_pycharm\lib\site-packages\flask\app.py", line 1523, in full_dispatch_request
    rv = self.dispatch_request()
  File "C:\Users\buset\anaconda3\envs\atc_pycharm\lib\site-packages\flask\app.py", line 1509, in dispatch_request
    return self.ensure_sync(self.view_functions[rule.endpoint])(**req.view_args)
  File "D:/atc/app.py", line 718, in submitOrder
    order_item_products["size"][i]=order_item_products["weight"][i]
  File "C:\Users\buset\anaconda3\envs\atc_pycharm\lib\site-packages\pandas\core\frame.py", line 3505, in __getitem__
    indexer = self.columns.get_loc(key)
  File "C:\Users\buset\anaconda3\envs\atc_pycharm\lib\site-packages\pandas\core\indexes\base.py", line 3623, in get_loc
    raise KeyError(key) from err
KeyError: 'weight'
Exception on /api/returnOrder [POST]
Traceback (most recent call last):
  File "C:\Users\buset\anaconda3\envs\atc_pycharm\lib\site-packages\flask\app.py", line 2077, in wsgi_app
    response = self.full_dispatch_request()
  File "C:\Users\buset\anaconda3\envs\atc_pycharm\lib\site-packages\flask\app.py", line 1525, in full_dispatch_request
    rv = self.handle_user_exception(e)
  File "C:\Users\buset\anaconda3\envs\atc_pycharm\lib\site-packages\flask\app.py", line 1523, in full_dispatch_request
    rv = self.dispatch_request()
  File "C:\Users\buset\anaconda3\envs\atc_pycharm\lib\site-packages\flask\app.py", line 1509, in dispatch_request
    return self.ensure_sync(self.view_functions[rule.endpoint])(**req.view_args)
  File "D:/atc/app.py", line 839, in returnOrder
    old_count=(row2[0][0])
IndexError: list index out of range
